Running ExUnit with seed: 898889, max_cases: 32



  1) test update/3 fails to update a tweet with missing content (Twitter.Support.TweetTest)
     test/support/tweet_test.exs:61
     ** (ArgumentError) errors were found at the given arguments:

       * 1st argument: table name already exists

     stacktrace:
       (stdlib 6.0.1) :ets.new(Twitter.Support.Tweet, [:named_table, :set, :public])
       test/support/tweet_test.exs:7: Twitter.Support.TweetTest.__ex_unit_setup_0/1
       test/support/tweet_test.exs:1: Twitter.Support.TweetTest.__ex_unit__/2



  2) test read_by_id/1 retrieves a tweet by ID (Twitter.Support.TweetTest)
     test/support/tweet_test.exs:36
     ** (ArgumentError) errors were found at the given arguments:

       * 1st argument: table name already exists

     stacktrace:
       (stdlib 6.0.1) :ets.new(Twitter.Support.Tweet, [:named_table, :set, :public])
       test/support/tweet_test.exs:7: Twitter.Support.TweetTest.__ex_unit_setup_0/1
       test/support/tweet_test.exs:1: Twitter.Support.TweetTest.__ex_unit__/2



  3) test destroy/2 destroys a tweet successfully (Twitter.Support.TweetTest)
     test/support/tweet_test.exs:72
     ** (ArgumentError) errors were found at the given arguments:

       * 1st argument: table name already exists

     stacktrace:
       (stdlib 6.0.1) :ets.new(Twitter.Support.Tweet, [:named_table, :set, :public])
       test/support/tweet_test.exs:7: Twitter.Support.TweetTest.__ex_unit_setup_0/1
       test/support/tweet_test.exs:1: Twitter.Support.TweetTest.__ex_unit__/2



  4) test destroy/2 fails to destroy a non-existent tweet (Twitter.Support.TweetTest)
     test/support/tweet_test.exs:78
     ** (ArgumentError) errors were found at the given arguments:

       * 1st argument: table name already exists

     stacktrace:
       (stdlib 6.0.1) :ets.new(Twitter.Support.Tweet, [:named_table, :set, :public])
       test/support/tweet_test.exs:7: Twitter.Support.TweetTest.__ex_unit_setup_0/1
       test/support/tweet_test.exs:1: Twitter.Support.TweetTest.__ex_unit__/2



  5) test create/2 creates a tweet with valid attributes (Twitter.Support.TweetTest)
     test/support/tweet_test.exs:12
     ** (ArgumentError) errors were found at the given arguments:

       * 1st argument: table name already exists

     stacktrace:
       (stdlib 6.0.1) :ets.new(Twitter.Support.Tweet, [:named_table, :set, :public])
       test/support/tweet_test.exs:7: Twitter.Support.TweetTest.__ex_unit_setup_0/1
       test/support/tweet_test.exs:1: Twitter.Support.TweetTest.__ex_unit__/2



  6) test read_by_user/1 retrieves tweets by user ID (Twitter.Support.TweetTest)
     test/support/tweet_test.exs:91
     ** (ArgumentError) errors were found at the given arguments:

       * 1st argument: table name already exists

     stacktrace:
       (stdlib 6.0.1) :ets.new(Twitter.Support.Tweet, [:named_table, :set, :public])
       test/support/tweet_test.exs:7: Twitter.Support.TweetTest.__ex_unit_setup_0/1
       test/support/tweet_test.exs:1: Twitter.Support.TweetTest.__ex_unit__/2



  7) test create/2 fails to create a tweet with missing content (Twitter.Support.TweetTest)
     test/support/tweet_test.exs:21
     ** (ArgumentError) errors were found at the given arguments:

       * 1st argument: table name already exists

     stacktrace:
       (stdlib 6.0.1) :ets.new(Twitter.Support.Tweet, [:named_table, :set, :public])
       test/support/tweet_test.exs:7: Twitter.Support.TweetTest.__ex_unit_setup_0/1
       test/support/tweet_test.exs:1: Twitter.Support.TweetTest.__ex_unit__/2



  8) test create/2 fails to create a tweet with invalid user_id (Twitter.Support.TweetTest)
     test/support/tweet_test.exs:25
     ** (ArgumentError) errors were found at the given arguments:

       * 1st argument: table name already exists

     stacktrace:
       (stdlib 6.0.1) :ets.new(Twitter.Support.Tweet, [:named_table, :set, :public])
       test/support/tweet_test.exs:7: Twitter.Support.TweetTest.__ex_unit_setup_0/1
       test/support/tweet_test.exs:1: Twitter.Support.TweetTest.__ex_unit__/2



  9) test read_by_user/1 returns an empty list for a user with no tweets (Twitter.Support.TweetTest)
     test/support/tweet_test.exs:98
     ** (ArgumentError) errors were found at the given arguments:

       * 1st argument: table name already exists

     stacktrace:
       (stdlib 6.0.1) :ets.new(Twitter.Support.Tweet, [:named_table, :set, :public])
       test/support/tweet_test.exs:7: Twitter.Support.TweetTest.__ex_unit_setup_0/1
       test/support/tweet_test.exs:1: Twitter.Support.TweetTest.__ex_unit__/2



 10) test read_by_id/1 returns an error when tweet is not found (Twitter.Support.TweetTest)
     test/support/tweet_test.exs:43
     ** (ArgumentError) errors were found at the given arguments:

       * 1st argument: table name already exists

     stacktrace:
       (stdlib 6.0.1) :ets.new(Twitter.Support.Tweet, [:named_table, :set, :public])
       test/support/tweet_test.exs:7: Twitter.Support.TweetTest.__ex_unit_setup_0/1
       test/support/tweet_test.exs:1: Twitter.Support.TweetTest.__ex_unit__/2



 11) test update/3 updates a tweet with valid attributes (Twitter.Support.TweetTest)
     test/support/tweet_test.exs:54
     ** (ArgumentError) errors were found at the given arguments:

       * 1st argument: table name already exists

     stacktrace:
       (stdlib 6.0.1) :ets.new(Twitter.Support.Tweet, [:named_table, :set, :public])
       test/support/tweet_test.exs:7: Twitter.Support.TweetTest.__ex_unit_setup_0/1
       test/support/tweet_test.exs:1: Twitter.Support.TweetTest.__ex_unit__/2



 12) test update/4 updates a user with valid attributes (Twitter.Support.UserTest)
     test/support/user_test.exs:74
     ** (ArgumentError) errors were found at the given arguments:

       * 1st argument: table name already exists

     stacktrace:
       (stdlib 6.0.1) :ets.new(Twitter.Support.User, [:named_table, :set, :public])
       test/support/user_test.exs:7: Twitter.Support.UserTest.__ex_unit_setup_0/1
       test/support/user_test.exs:1: Twitter.Support.UserTest.__ex_unit__/2



 13) test create/3 fails to create a user with age below 13 (Twitter.Support.UserTest)
     test/support/user_test.exs:34
     ** (ArgumentError) errors were found at the given arguments:

       * 1st argument: table name already exists

     stacktrace:
       (stdlib 6.0.1) :ets.new(Twitter.Support.User, [:named_table, :set, :public])
       test/support/user_test.exs:7: Twitter.Support.UserTest.__ex_unit_setup_0/1
       test/support/user_test.exs:1: Twitter.Support.UserTest.__ex_unit__/2



 14) test update/4 fails to update a user with missing username (Twitter.Support.UserTest)
     test/support/user_test.exs:83
     ** (ArgumentError) errors were found at the given arguments:

       * 1st argument: table name already exists

     stacktrace:
       (stdlib 6.0.1) :ets.new(Twitter.Support.User, [:named_table, :set, :public])
       test/support/user_test.exs:7: Twitter.Support.UserTest.__ex_unit_setup_0/1
       test/support/user_test.exs:1: Twitter.Support.UserTest.__ex_unit__/2



 15) test update/4 fails to update a user with invalid email (Twitter.Support.UserTest)
     test/support/user_test.exs:88
     ** (ArgumentError) errors were found at the given arguments:

       * 1st argument: table name already exists

     stacktrace:
       (stdlib 6.0.1) :ets.new(Twitter.Support.User, [:named_table, :set, :public])
       test/support/user_test.exs:7: Twitter.Support.UserTest.__ex_unit_setup_0/1
       test/support/user_test.exs:1: Twitter.Support.UserTest.__ex_unit__/2



 16) test create/3 creates a user with valid attributes (Twitter.Support.UserTest)
     test/support/user_test.exs:12
     ** (ArgumentError) errors were found at the given arguments:

       * 1st argument: table name already exists

     stacktrace:
       (stdlib 6.0.1) :ets.new(Twitter.Support.User, [:named_table, :set, :public])
       test/support/user_test.exs:7: Twitter.Support.UserTest.__ex_unit_setup_0/1
       test/support/user_test.exs:1: Twitter.Support.UserTest.__ex_unit__/2



 17) test update/4 fails to update a user with age below 13 (Twitter.Support.UserTest)
     test/support/user_test.exs:92
     ** (ArgumentError) errors were found at the given arguments:

       * 1st argument: table name already exists

     stacktrace:
       (stdlib 6.0.1) :ets.new(Twitter.Support.User, [:named_table, :set, :public])
       test/support/user_test.exs:7: Twitter.Support.UserTest.__ex_unit_setup_0/1
       test/support/user_test.exs:1: Twitter.Support.UserTest.__ex_unit__/2



 18) test create/3 fails to create a user with missing username (Twitter.Support.UserTest)
     test/support/user_test.exs:21
     ** (ArgumentError) errors were found at the given arguments:

       * 1st argument: table name already exists

     stacktrace:
       (stdlib 6.0.1) :ets.new(Twitter.Support.User, [:named_table, :set, :public])
       test/support/user_test.exs:7: Twitter.Support.UserTest.__ex_unit_setup_0/1
       test/support/user_test.exs:1: Twitter.Support.UserTest.__ex_unit__/2



 19) test create/3 fails to create a user with invalid email (Twitter.Support.UserTest)
     test/support/user_test.exs:27
     ** (ArgumentError) errors were found at the given arguments:

       * 1st argument: table name already exists

     stacktrace:
       (stdlib 6.0.1) :ets.new(Twitter.Support.User, [:named_table, :set, :public])
       test/support/user_test.exs:7: Twitter.Support.UserTest.__ex_unit_setup_0/1
       test/support/user_test.exs:1: Twitter.Support.UserTest.__ex_unit__/2



 20) test destroy/1 destroys a user successfully (Twitter.Support.UserTest)
     test/support/user_test.exs:108
     ** (ArgumentError) errors were found at the given arguments:

       * 1st argument: table name already exists

     stacktrace:
       (stdlib 6.0.1) :ets.new(Twitter.Support.User, [:named_table, :set, :public])
       test/support/user_test.exs:7: Twitter.Support.UserTest.__ex_unit_setup_0/1
       test/support/user_test.exs:1: Twitter.Support.UserTest.__ex_unit__/2



 21) test read_by_id/1 retrieves a user by ID (Twitter.Support.UserTest)
     test/support/user_test.exs:53
     ** (ArgumentError) errors were found at the given arguments:

       * 1st argument: table name already exists

     stacktrace:
       (stdlib 6.0.1) :ets.new(Twitter.Support.User, [:named_table, :set, :public])
       test/support/user_test.exs:7: Twitter.Support.UserTest.__ex_unit_setup_0/1
       test/support/user_test.exs:1: Twitter.Support.UserTest.__ex_unit__/2



 22) test destroy/1 fails to destroy a non-existent user (Twitter.Support.UserTest)
     test/support/user_test.exs:114
     ** (ArgumentError) errors were found at the given arguments:

       * 1st argument: table name already exists

     stacktrace:
       (stdlib 6.0.1) :ets.new(Twitter.Support.User, [:named_table, :set, :public])
       test/support/user_test.exs:7: Twitter.Support.UserTest.__ex_unit_setup_0/1
       test/support/user_test.exs:1: Twitter.Support.UserTest.__ex_unit__/2



 23) test read_by_id/1 returns an error when user is not found (Twitter.Support.UserTest)
     test/support/user_test.exs:62
     ** (ArgumentError) errors were found at the given arguments:

       * 1st argument: table name already exists

     stacktrace:
       (stdlib 6.0.1) :ets.new(Twitter.Support.User, [:named_table, :set, :public])
       test/support/user_test.exs:7: Twitter.Support.UserTest.__ex_unit_setup_0/1
       test/support/user_test.exs:1: Twitter.Support.UserTest.__ex_unit__/2


01:39:54.011 [debug] Creating Twitter.Support.User:

%{
  id: "434f08c8-85c3-458b-b391-07de63202b2c",
  username: "john_doe",
  email: "john.doe@example.com",
  age: 25,
  inserted_at: ~U[2024-09-06 08:39:53.997455Z],
  updated_at: ~U[2024-09-06 08:39:53.999817Z]
}


01:39:54.017 [debug] Creating Twitter.Support.Tweet:

%{
  id: "3b423459-4477-46d8-98ed-d16056e7e602",
  status: :draft,
  content: "Hello, world!",
  user_id: "434f08c8-85c3-458b-b391-07de63202b2c",
  inserted_at: ~U[2024-09-06 08:39:54.017316Z],
  updated_at: ~U[2024-09-06 08:39:54.017321Z]
}


01:39:54.017 [debug] Creating Twitter.Support.Tweet:

%{
  id: "117811fe-3c55-4d89-9096-6074dee7a875",
  status: :draft,
  content: "Another tweet",
  user_id: "434f08c8-85c3-458b-b391-07de63202b2c",
  inserted_at: ~U[2024-09-06 08:39:54.017535Z],
  updated_at: ~U[2024-09-06 08:39:54.017536Z]
}

.
01:39:54.043 [debug] Creating Twitter.Support.User:

%{
  id: "70496e67-4492-42fb-857d-7ed0d47cc9e3",
  username: "john_doe",
  email: "john.doe@example.com",
  age: 25,
  inserted_at: ~U[2024-09-06 08:39:54.043611Z],
  updated_at: ~U[2024-09-06 08:39:54.043618Z]
}


01:39:54.043 [debug] Creating Twitter.Support.Tweet:

%{
  id: "b07f58ca-f563-471d-bcaf-af53defe02ef",
  status: :draft,
  content: "Hello, world!",
  user_id: "70496e67-4492-42fb-857d-7ed0d47cc9e3",
  inserted_at: ~U[2024-09-06 08:39:54.043818Z],
  updated_at: ~U[2024-09-06 08:39:54.043820Z]
}


01:39:54.044 [debug] Creating Twitter.Support.Tweet:

%{
  id: "f3d5a108-579f-4929-9289-437596832fcc",
  status: :draft,
  content: "Another tweet",
  user_id: "70496e67-4492-42fb-857d-7ed0d47cc9e3",
  inserted_at: ~U[2024-09-06 08:39:54.044017Z],
  updated_at: ~U[2024-09-06 08:39:54.044019Z]
}

.
01:39:54.044 [debug] Creating Twitter.Support.User:

%{
  id: "c8d2c61f-4dbd-408d-ac68-a3479446eb1d",
  username: "john_doe",
  email: "john.doe@example.com",
  age: 25,
  inserted_at: ~U[2024-09-06 08:39:54.044569Z],
  updated_at: ~U[2024-09-06 08:39:54.044576Z]
}


01:39:54.044 [debug] Creating Twitter.Support.Tweet:

%{
  id: "9724cfdc-8f53-4ce7-897d-3560a81d9475",
  status: :draft,
  content: "Hello, world!",
  user_id: "c8d2c61f-4dbd-408d-ac68-a3479446eb1d",
  inserted_at: ~U[2024-09-06 08:39:54.044767Z],
  updated_at: ~U[2024-09-06 08:39:54.044769Z]
}


01:39:54.044 [debug] Creating Twitter.Support.Tweet:

%{
  id: "50a667cb-516f-4359-8bad-518c5f31de46",
  status: :draft,
  content: "Another tweet",
  user_id: "c8d2c61f-4dbd-408d-ac68-a3479446eb1d",
  inserted_at: ~U[2024-09-06 08:39:54.044936Z],
  updated_at: ~U[2024-09-06 08:39:54.044937Z]
}

.

 24) test instruct! returns a response (AshAiTest)
     test/ash_ai_test.exs:20
     ** (MatchError) no match of right hand side value: {:error, %Ash.Error.Unknown{changeset: "#Changeset<>",  errors: [%Ash.Error.Unknown.UnknownError{error: "unknown error: :table_not_found", field: nil, value: nil, splode: Ash.Error, bread_crumbs: [], vars: [], path: [], stacktrace: #Splode.Stacktrace<>, class: :unknown}]}}
     stacktrace:
       test/ash_ai_test.exs:10: AshAiTest.__ex_unit_setup_0/1
       test/ash_ai_test.exs:1: AshAiTest.__ex_unit__/2



 25) test creates a user account (AshAiTest)
     test/ash_ai_test.exs:58
     ** (MatchError) no match of right hand side value: {:error, %Ash.Error.Unknown{changeset: "#Changeset<>",  errors: [%Ash.Error.Unknown.UnknownError{error: "unknown error: :table_not_found", field: nil, value: nil, splode: Ash.Error, bread_crumbs: [], vars: [], path: [], stacktrace: #Splode.Stacktrace<>, class: :unknown}]}}
     stacktrace:
       test/ash_ai_test.exs:10: AshAiTest.__ex_unit_setup_0/1
       test/ash_ai_test.exs:1: AshAiTest.__ex_unit__/2



 26) test updates user age (AshAiTest)
     test/ash_ai_test.exs:124
     ** (MatchError) no match of right hand side value: {:error, %Ash.Error.Unknown{changeset: "#Changeset<>",  errors: [%Ash.Error.Unknown.UnknownError{error: "unknown error: :table_not_found", field: nil, value: nil, splode: Ash.Error, bread_crumbs: [], vars: [], path: [], stacktrace: #Splode.Stacktrace<>, class: :unknown}]}}
     stacktrace:
       test/ash_ai_test.exs:10: AshAiTest.__ex_unit_setup_0/1
       test/ash_ai_test.exs:1: AshAiTest.__ex_unit__/2



 27) test AI correctly updates Jane Doe's age (AshAiUpdateTest)
     test/ash_ai_update_test.exs:14
     ** (Ash.Error.Unknown) Unknown Error

     * unknown error: :table_not_found
       (ash 3.4.1) /Users/sac/dev/ash_ai/deps/splode/lib/splode.ex:291: Ash.Error.to_error/2
       (ash 3.4.1) lib/ash/actions/helpers.ex:15: Ash.Actions.Helpers.rollback_if_in_transaction/3
       (ash 3.4.1) lib/ash/actions/create/create.ex:377: anonymous fn/6 in Ash.Actions.Create.commit/3
       (ash 3.4.1) lib/ash/changeset/changeset.ex:3621: Ash.Changeset.run_around_actions/2
       (ash 3.4.1) lib/ash/changeset/changeset.ex:3304: anonymous fn/2 in Ash.Changeset.transaction_hooks/2
       (ash 3.4.1) lib/ash/changeset/changeset.ex:3214: Ash.Changeset.with_hooks/3
       (ash 3.4.1) lib/ash/actions/create/create.ex:236: Ash.Actions.Create.commit/3
       (ash 3.4.1) lib/ash/actions/create/create.ex:108: Ash.Actions.Create.do_run/4
       (ash 3.4.1) lib/ash/actions/create/create.ex:46: Ash.Actions.Create.run/4
       (ash 3.4.1) lib/ash.ex:2038: Ash.create!/3
       test/ash_ai_update_test.exs:9: AshAiUpdateTest.__ex_unit_setup_0/1
       test/ash_ai_update_test.exs:1: AshAiUpdateTest.__ex_unit__/2
       (ex_unit 1.17.2) lib/ex_unit/runner.ex:478: ExUnit.Runner.exec_test_setup/2
       (ex_unit 1.17.2) lib/ex_unit/runner.ex:411: anonymous fn/2 in ExUnit.Runner.spawn_test_monitor/4
       (stdlib 6.0.1) timer.erl:590: :timer.tc/2
       (ex_unit 1.17.2) lib/ex_unit/runner.ex:407: anonymous fn/6 in ExUnit.Runner.spawn_test_monitor/4
     stacktrace:
       (elixir 1.17.2) lib/process.ex:864: Process.info/2
       (ash 3.4.1) lib/ash/error/unknown.ex:3: Ash.Error.Unknown."exception (overridable 2)"/1
       (ash 3.4.1) /Users/sac/dev/ash_ai/deps/splode/lib/splode.ex:211: Ash.Error.to_class/2
       (ash 3.4.1) lib/ash/error/error.ex:66: Ash.Error.to_error_class/2
       (ash 3.4.1) lib/ash/actions/create/create.ex:137: Ash.Actions.Create.do_run/4
       (ash 3.4.1) lib/ash/actions/create/create.ex:46: Ash.Actions.Create.run/4
       (ash 3.4.1) lib/ash.ex:2038: Ash.create!/3
       test/ash_ai_update_test.exs:9: AshAiUpdateTest.__ex_unit_setup_0/1
       test/ash_ai_update_test.exs:1: AshAiUpdateTest.__ex_unit__/2



 28) test AI performs all actions: create, read, update, destroy (AshAiAllActionsTest)
     test/ash_ai_all_actions_test.exs:15
     ** (Ash.Error.Unknown) Unknown Error

     * unknown error: :table_not_found
       (ash 3.4.1) /Users/sac/dev/ash_ai/deps/splode/lib/splode.ex:291: Ash.Error.to_error/2
       (ash 3.4.1) lib/ash/actions/helpers.ex:15: Ash.Actions.Helpers.rollback_if_in_transaction/3
       (ash 3.4.1) lib/ash/actions/create/create.ex:377: anonymous fn/6 in Ash.Actions.Create.commit/3
       (ash 3.4.1) lib/ash/changeset/changeset.ex:3621: Ash.Changeset.run_around_actions/2
       (ash 3.4.1) lib/ash/changeset/changeset.ex:3304: anonymous fn/2 in Ash.Changeset.transaction_hooks/2
       (ash 3.4.1) lib/ash/changeset/changeset.ex:3214: Ash.Changeset.with_hooks/3
       (ash 3.4.1) lib/ash/actions/create/create.ex:236: Ash.Actions.Create.commit/3
       (ash 3.4.1) lib/ash/actions/create/create.ex:108: Ash.Actions.Create.do_run/4
       (ash 3.4.1) lib/ash/actions/create/create.ex:46: Ash.Actions.Create.run/4
       (ash 3.4.1) lib/ash.ex:2038: Ash.create!/3
       test/ash_ai_all_actions_test.exs:10: AshAiAllActionsTest.__ex_unit_setup_0/1
       test/ash_ai_all_actions_test.exs:1: AshAiAllActionsTest.__ex_unit__/2
       (ex_unit 1.17.2) lib/ex_unit/runner.ex:478: ExUnit.Runner.exec_test_setup/2
       (ex_unit 1.17.2) lib/ex_unit/runner.ex:411: anonymous fn/2 in ExUnit.Runner.spawn_test_monitor/4
       (stdlib 6.0.1) timer.erl:590: :timer.tc/2
       (ex_unit 1.17.2) lib/ex_unit/runner.ex:407: anonymous fn/6 in ExUnit.Runner.spawn_test_monitor/4
     stacktrace:
       (elixir 1.17.2) lib/process.ex:864: Process.info/2
       (ash 3.4.1) lib/ash/error/unknown.ex:3: Ash.Error.Unknown."exception (overridable 2)"/1
       (ash 3.4.1) /Users/sac/dev/ash_ai/deps/splode/lib/splode.ex:211: Ash.Error.to_class/2
       (ash 3.4.1) lib/ash/error/error.ex:66: Ash.Error.to_error_class/2
       (ash 3.4.1) lib/ash/actions/create/create.ex:137: Ash.Actions.Create.do_run/4
       (ash 3.4.1) lib/ash/actions/create/create.ex:46: Ash.Actions.Create.run/4
       (ash 3.4.1) lib/ash.ex:2038: Ash.create!/3
       test/ash_ai_all_actions_test.exs:10: AshAiAllActionsTest.__ex_unit_setup_0/1
       test/ash_ai_all_actions_test.exs:1: AshAiAllActionsTest.__ex_unit__/2



 29) test AI invokes correct action for reading user by username and handles completion (AshAiReadTest)
     test/ash_ai_read_test.exs:15
     ** (Ash.Error.Unknown) Unknown Error

     * unknown error: :table_not_found
       (ash 3.4.1) /Users/sac/dev/ash_ai/deps/splode/lib/splode.ex:291: Ash.Error.to_error/2
       (ash 3.4.1) lib/ash/actions/helpers.ex:15: Ash.Actions.Helpers.rollback_if_in_transaction/3
       (ash 3.4.1) lib/ash/actions/create/create.ex:377: anonymous fn/6 in Ash.Actions.Create.commit/3
       (ash 3.4.1) lib/ash/changeset/changeset.ex:3621: Ash.Changeset.run_around_actions/2
       (ash 3.4.1) lib/ash/changeset/changeset.ex:3304: anonymous fn/2 in Ash.Changeset.transaction_hooks/2
       (ash 3.4.1) lib/ash/changeset/changeset.ex:3214: Ash.Changeset.with_hooks/3
       (ash 3.4.1) lib/ash/actions/create/create.ex:236: Ash.Actions.Create.commit/3
       (ash 3.4.1) lib/ash/actions/create/create.ex:108: Ash.Actions.Create.do_run/4
       (ash 3.4.1) lib/ash/actions/create/create.ex:46: Ash.Actions.Create.run/4
       (ash 3.4.1) lib/ash.ex:2038: Ash.create!/3
       test/ash_ai_read_test.exs:10: AshAiReadTest.__ex_unit_setup_0/1
       test/ash_ai_read_test.exs:1: AshAiReadTest.__ex_unit__/2
       (ex_unit 1.17.2) lib/ex_unit/runner.ex:478: ExUnit.Runner.exec_test_setup/2
       (ex_unit 1.17.2) lib/ex_unit/runner.ex:411: anonymous fn/2 in ExUnit.Runner.spawn_test_monitor/4
       (stdlib 6.0.1) timer.erl:590: :timer.tc/2
       (ex_unit 1.17.2) lib/ex_unit/runner.ex:407: anonymous fn/6 in ExUnit.Runner.spawn_test_monitor/4
     stacktrace:
       (elixir 1.17.2) lib/process.ex:864: Process.info/2
       (ash 3.4.1) lib/ash/error/unknown.ex:3: Ash.Error.Unknown."exception (overridable 2)"/1
       (ash 3.4.1) /Users/sac/dev/ash_ai/deps/splode/lib/splode.ex:211: Ash.Error.to_class/2
       (ash 3.4.1) lib/ash/error/error.ex:66: Ash.Error.to_error_class/2
       (ash 3.4.1) lib/ash/actions/create/create.ex:137: Ash.Actions.Create.do_run/4
       (ash 3.4.1) lib/ash/actions/create/create.ex:46: Ash.Actions.Create.run/4
       (ash 3.4.1) lib/ash.ex:2038: Ash.create!/3
       test/ash_ai_read_test.exs:10: AshAiReadTest.__ex_unit_setup_0/1
       test/ash_ai_read_test.exs:1: AshAiReadTest.__ex_unit__/2


Finished in 0.1 seconds (0.1s async, 0.00s sync)
32 tests, 29 failures
